{"timestamp":"2025-05-22T03:59:11.855067","level":"info","event":"DAG bundles loaded: dags-folder","logger":"airflow.dag_processing.bundles.manager.DagBundlesManager"}
{"timestamp":"2025-05-22T03:59:11.856573","level":"info","event":"Filling up the DagBag from /opt/airflow/dags/weather_data_etl_pipeline.py","logger":"airflow.models.dagbag.DagBag"}
{"timestamp":"2025-05-22T03:59:12.028160","level":"info","event":"Secrets backends loaded for worker","count":1,"backend_classes":["EnvironmentVariablesBackend"],"logger":"supervisor"}
{"timestamp":"2025-05-22T03:59:13.642246","level":"info","event":"Connection Retrieved 'open_meteo_api'","logger":"airflow.hooks.base"}
{"timestamp":"2025-05-22T03:59:34.879017","level":"warning","event":"HTTPSConnectionPool(host='api.open-meteo.com', port=443): Max retries exceeded with url: /v1/forecast?latitude=27.619339&longitude=85.538522&current_weather=true (Caused by NewConnectionError('<urllib3.connection.HTTPSConnection object at 0x7f77975b39b0>: Failed to establish a new connection: [Errno 101] Network is unreachable')) Tenacity will retry to execute the operation","logger":"airflow.task.hooks.airflow.providers.http.hooks.http.HttpHook"}
{"timestamp":"2025-05-22T03:59:34.879436","level":"error","event":"Task failed with exception","logger":"task","error_detail":[{"exc_type":"ConnectionError","exc_value":"HTTPSConnectionPool(host='api.open-meteo.com', port=443): Max retries exceeded with url: /v1/forecast?latitude=27.619339&longitude=85.538522&current_weather=true (Caused by NewConnectionError('<urllib3.connection.HTTPSConnection object at 0x7f77975b39b0>: Failed to establish a new connection: [Errno 101] Network is unreachable'))","exc_notes":[],"syntax_error":null,"is_cause":false,"frames":[{"filename":"/home/airflow/.local/lib/python3.12/site-packages/airflow/sdk/execution_time/task_runner.py","lineno":838,"name":"run"},{"filename":"/home/airflow/.local/lib/python3.12/site-packages/airflow/sdk/execution_time/task_runner.py","lineno":1130,"name":"_execute_task"},{"filename":"/home/airflow/.local/lib/python3.12/site-packages/airflow/sdk/bases/operator.py","lineno":408,"name":"wrapper"},{"filename":"/home/airflow/.local/lib/python3.12/site-packages/airflow/sdk/bases/decorator.py","lineno":251,"name":"execute"},{"filename":"/home/airflow/.local/lib/python3.12/site-packages/airflow/sdk/bases/operator.py","lineno":408,"name":"wrapper"},{"filename":"/home/airflow/.local/lib/python3.12/site-packages/airflow/providers/standard/operators/python.py","lineno":212,"name":"execute"},{"filename":"/home/airflow/.local/lib/python3.12/site-packages/airflow/providers/standard/operators/python.py","lineno":235,"name":"execute_callable"},{"filename":"/home/airflow/.local/lib/python3.12/site-packages/airflow/sdk/execution_time/callback_runner.py","lineno":81,"name":"run"},{"filename":"/opt/airflow/dags/weather_data_etl_pipeline.py","lineno":43,"name":"extract_weather_data"},{"filename":"/home/airflow/.local/lib/python3.12/site-packages/airflow/providers/http/hooks/http.py","lineno":265,"name":"run"},{"filename":"/home/airflow/.local/lib/python3.12/site-packages/airflow/providers/http/hooks/http.py","lineno":323,"name":"run_and_check"},{"filename":"/home/airflow/.local/lib/python3.12/site-packages/airflow/providers/http/hooks/http.py","lineno":315,"name":"run_and_check"},{"filename":"/home/airflow/.local/lib/python3.12/site-packages/requests/sessions.py","lineno":703,"name":"send"},{"filename":"/home/airflow/.local/lib/python3.12/site-packages/requests/adapters.py","lineno":700,"name":"send"}]},{"exc_type":"MaxRetryError","exc_value":"HTTPSConnectionPool(host='api.open-meteo.com', port=443): Max retries exceeded with url: /v1/forecast?latitude=27.619339&longitude=85.538522&current_weather=true (Caused by NewConnectionError('<urllib3.connection.HTTPSConnection object at 0x7f77975b39b0>: Failed to establish a new connection: [Errno 101] Network is unreachable'))","exc_notes":[],"syntax_error":null,"is_cause":false,"frames":[{"filename":"/home/airflow/.local/lib/python3.12/site-packages/requests/adapters.py","lineno":667,"name":"send"},{"filename":"/home/airflow/.local/lib/python3.12/site-packages/urllib3/connectionpool.py","lineno":841,"name":"urlopen"},{"filename":"/home/airflow/.local/lib/python3.12/site-packages/urllib3/util/retry.py","lineno":519,"name":"increment"}]},{"exc_type":"NewConnectionError","exc_value":"<urllib3.connection.HTTPSConnection object at 0x7f77975b39b0>: Failed to establish a new connection: [Errno 101] Network is unreachable","exc_notes":[],"syntax_error":null,"is_cause":true,"frames":[{"filename":"/home/airflow/.local/lib/python3.12/site-packages/urllib3/connectionpool.py","lineno":787,"name":"urlopen"},{"filename":"/home/airflow/.local/lib/python3.12/site-packages/urllib3/connectionpool.py","lineno":488,"name":"_make_request"},{"filename":"/home/airflow/.local/lib/python3.12/site-packages/urllib3/connectionpool.py","lineno":464,"name":"_make_request"},{"filename":"/home/airflow/.local/lib/python3.12/site-packages/urllib3/connectionpool.py","lineno":1093,"name":"_validate_conn"},{"filename":"/home/airflow/.local/lib/python3.12/site-packages/urllib3/connection.py","lineno":704,"name":"connect"},{"filename":"/home/airflow/.local/lib/python3.12/site-packages/urllib3/connection.py","lineno":213,"name":"_new_conn"}]},{"exc_type":"OSError","exc_value":"[Errno 101] Network is unreachable","exc_notes":[],"syntax_error":null,"is_cause":true,"frames":[{"filename":"/home/airflow/.local/lib/python3.12/site-packages/urllib3/connection.py","lineno":198,"name":"_new_conn"},{"filename":"/home/airflow/.local/lib/python3.12/site-packages/urllib3/util/connection.py","lineno":85,"name":"create_connection"},{"filename":"/home/airflow/.local/lib/python3.12/site-packages/urllib3/util/connection.py","lineno":73,"name":"create_connection"}]}]}
